Workbook

Sheet Summary
A1: Year: 2020 | B1: Figures | F1: Papers | M1: % of all papers | P1: % of SBOL possible papers
A2: Year | B2: Total | C2: SBOL possible | D2: SBOL compliant | E2: Best Practices | F2: SBOL possible | G2: Partial Compliant | H2: Fully Compliant | I2: Partial Best | J2: Fully Best | K2: Total | M2: SBOL possible | N2: Partial Compliant | O2: Fully Compliant | P2: Partial Compliant | Q2: Fully Compliant | R2: Part Best | S2: Full Best | T2: % of Figures | U2: % Possible Figures | V2: % Best Practices
A3: January | B3: =January!C22 -> 89 | C3: =January!D22 -> 31 | D3: =January!E22 -> 25 | E3: =January!F22 -> 14 | F3: =January!G22 -> 14 | G3: =January!H22 -> 10 | H3: =January!I22 -> 10 | I3: =January!J22 -> 5 | ... K3: =January!L22 -> 19 | M3: =F3/$K3 -> 0.73684211 | N3: =G3/$K3 -> 0.52631579 | O3: =H3/$K3 -> 0.52631579 | P3: =G3/$F3 -> 0.71428571 | Q3: =H3/$F3 -> 0.71428571 | R3: =I3/F3 -> 0.35714286 | S3: =J3/F3 -> 0.28571429 | T3: =D3/$B3 -> 0.28089888 | U3: =D3/C3 -> 0.80645161 | V3: =E3/C3 -> 0.4516129
A4: February | B4: =February!C31 -> 152 | C4: =February!D31 -> 37 | D4: =February!E31 -> 34 | E4: =February!F31 -> 25 | F4: =February!G31 -> 15 | G4: =February!H31 -> 14 | H4: =February!I31 -> 13 | I4: =February!J31 -> 11 | ... K4: =February!L31 -> 28 | M4: =F4/$K4 -> 0.53571429 | N4: =G4/$K4 -> 0.5 | O4: =H4/$K4 -> 0.46428571 | P4: =G4/$F4 -> 0.93333333 | Q4: =H4/$F4 -> 0.86666667 | R4: =I4/F4 -> 0.73333333 | S4: =J4/F4 -> 0.46666667 | T4: =D4/$B4 -> 0.22368421 | U4: =D4/C4 -> 0.91891892 | V4: =E4/C4 -> 0.67567568
A5: March | B5: =March!C26 -> 120 | C5: =March!D26 -> 23 | D5: =March!E26 -> 21 | E5: =March!F26 -> 7 | F5: =March!G26 -> 12 | G5: =March!H26 -> 10 | H5: =March!I26 -> 10 | I5: =March!J26 -> 5 | ... K5: =March!L26 -> 23 | M5: =F5/$K5 -> 0.52173913 | N5: =G5/$K5 -> 0.43478261 | O5: =H5/$K5 -> 0.43478261 | P5: =G5/$F5 -> 0.83333333 | Q5: =H5/$F5 -> 0.83333333 | R5: =I5/F5 -> 0.41666667 | S5: =J5/F5 -> 0.33333333 | T5: =D5/$B5 -> 0.175 | U5: =D5/C5 -> 0.91304348 | V5: =E5/C5 -> 0.30434783
A6: April | B6: =April!C29 -> 151 | C6: =April!D29 -> 28 | D6: =April!E29 -> 24 | E6: =April!F29 -> 13 | F6: =April!G29 -> 11 | G6: =April!H29 -> 9 | H6: =April!I29 -> 7 | I6: =April!J29 -> 5 | ... K6: =April!L29 -> 26 | M6: =F6/$K6 -> 0.42307692 | N6: =G6/$K6 -> 0.34615385 | O6: =H6/$K6 -> 0.26923077 | P6: =G6/$F6 -> 0.81818182 | Q6: =H6/$F6 -> 0.63636364 | R6: =I6/F6 -> 0.45454545 | S6: =J6/F6 -> 0.27272727 | T6: =D6/$B6 -> 0.1589404 | U6: =D6/C6 -> 0.85714286 | V6: =E6/C6 -> 0.46428571
A7: May | B7: =May!C27 -> 125 | C7: =May!D27 -> 31 | D7: =May!E27 -> 22 | E7: =May!F27 -> 13 | F7: =May!G27 -> 14 | G7: =May!H27 -> 8 | H7: =May!I27 -> 8 | I7: =May!J27 -> 6 | ... K7: =May!L27 -> 24 | M7: =F7/$K7 -> 0.58333333 | N7: =G7/$K7 -> 0.33333333 | O7: =H7/$K7 -> 0.33333333 | P7: =G7/$F7 -> 0.57142857 | Q7: =H7/$F7 -> 0.57142857 | R7: =I7/F7 -> 0.42857143 | S7: =J7/F7 -> 0.21428571 | T7: =D7/$B7 -> 0.176 | U7: =D7/C7 -> 0.70967742 | V7: =E7/C7 -> 0.41935484
A8: June | B8: =June!C31 -> 129 | C8: =June!D31 -> 37 | D8: =June!E31 -> 30 | E8: =June!F31 -> 8 | F8: =June!G31 -> 16 | G8: =June!H31 -> 13 | H8: =June!I31 -> 11 | I8: =June!J31 -> 4 | ... K8: =June!L31 -> 28 | M8: =F8/$K8 -> 0.57142857 | N8: =G8/$K8 -> 0.46428571 | O8: =H8/$K8 -> 0.39285714 | P8: =G8/$F8 -> 0.8125 | Q8: =H8/$F8 -> 0.6875 | R8: =I8/F8 -> 0.25 | S8: =J8/F8 -> 0.1875 | T8: =D8/$B8 -> 0.23255814 | U8: =D8/C8 -> 0.81081081 | V8: =E8/C8 -> 0.21621622
A9: July | B9: =July!C43 -> 179 | C9: =July!D43 -> 21 | D9: =July!E43 -> 19 | E9: =July!F43 -> 6 | F9: =July!G43 -> 11 | G9: =July!H43 -> 10 | H9: =July!I43 -> 10 | I9: =July!J43 -> 4 | ... K9: =July!L43 -> 30 | M9: =F9/$K9 -> 0.36666667 | N9: =G9/$K9 -> 0.33333333 | O9: =H9/$K9 -> 0.33333333 | P9: =G9/$F9 -> 0.90909091 | Q9: =H9/$F9 -> 0.90909091 | R9: =I9/F9 -> 0.36363636 | S9: =J9/F9 -> 0.36363636 | T9: =D9/$B9 -> 0.10614525 | U9: =D9/C9 -> 0.9047619 | V9: =E9/C9 -> 0.28571429
A10: August | B10: =August!C30 -> 139 | C10: =August!D30 -> 47 | D10: =August!E30 -> 28 | E10: =August!F30 -> 11 | F10: =August!G30 -> 18 | G10: =August!H30 -> 13 | H10: =August!I30 -> 11 | I10: =August!J30 -> 7 | ... K10: =August!L30 -> 27 | M10: =F10/$K10 -> 0.66666667 | N10: =G10/$K10 -> 0.48148148 | O10: =H10/$K10 -> 0.40740741 | P10: =G10/$F10 -> 0.72222222 | Q10: =H10/$F10 -> 0.61111111 | R10: =I10/F10 -> 0.38888889 | S10: =J10/F10 -> 0.27777778 | T10: =D10/$B10 -> 0.20143885 | U10: =D10/C10 -> 0.59574468 | V10: =E10/C10 -> 0.23404255
A11: September | B11: =September!C41 -> 181 | C11: =September!D41 -> 51 | D11: =September!E41 -> 37 | E11: =September!F41 -> 16 | F11: =September!G41 -> 20 | G11: =September!H41 -> 14 | H11: =September!I41 -> 14 | I11: =September!J41 -> 6 | ... K11: =September!L41 -> 30 | M11: =F11/$K11 -> 0.66666667 | N11: =G11/$K11 -> 0.46666667 | O11: =H11/$K11 -> 0.46666667 | P11: =G11/$F11 -> 0.7 | Q11: =H11/$F11 -> 0.7 | R11: =I11/F11 -> 0.3 | S11: =J11/F11 -> 0.3 | T11: =D11/$B11 -> 0.20441989 | U11: =D11/C11 -> 0.7254902 | V11: =E11/C11 -> 0.31372549
A12: October | B12: =October!C26 -> 125 | C12: =October!D26 -> 28 | D12: =October!E26 -> 14 | E12: =October!F26 -> 6 | F12: =October!G26 -> 14 | G12: =October!H26 -> 10 | H12: =October!I26 -> 9 | I12: =October!J26 -> 4 | ... K12: =October!L26 -> 23 | M12: =F12/$K12 -> 0.60869565 | N12: =G12/$K12 -> 0.43478261 | O12: =H12/$K12 -> 0.39130435 | P12: =G12/$F12 -> 0.71428571 | Q12: =H12/$F12 -> 0.64285714 | R12: =I12/F12 -> 0.28571429 | S12: =J12/F12 -> 0.28571429 | T12: =D12/$B12 -> 0.112 | U12: =D12/C12 -> 0.5 | V12: =E12/C12 -> 0.21428571
A13: November | B13: =November!C32 -> 145 | C13: =November!D32 -> 32 | D13: =November!E32 -> 25 | E13: =November!F32 -> 9 | F13: =November!G32 -> 15 | G13: =November!H32 -> 13 | H13: =November!I32 -> 11 | I13: =November!J32 -> 6 | ... K13: =November!L32 -> 29 | M13: =F13/$K13 -> 0.51724138 | N13: =G13/$K13 -> 0.44827586 | O13: =H13/$K13 -> 0.37931034 | P13: =G13/$F13 -> 0.86666667 | Q13: =H13/$F13 -> 0.73333333 | R13: =I13/F13 -> 0.4 | S13: =J13/F13 -> 0.33333333 | T13: =D13/$B13 -> 0.17241379 | U13: =D13/C13 -> 0.78125 | V13: =E13/C13 -> 0.28125
A14: December | B14: =December!C27 -> 114 | C14: =December!D27 -> 39 | D14: =December!E27 -> 29 | E14: =December!F27 -> 11 | F14: =December!G27 -> 17 | G14: =December!H27 -> 13 | H14: =December!I27 -> 12 | I14: =December!J27 -> 5 | ... K14: =December!L27 -> 24 | M14: =F14/$K14 -> 0.70833333 | N14: =G14/$K14 -> 0.54166667 | O14: =H14/$K14 -> 0.5 | P14: =G14/$F14 -> 0.76470588 | Q14: =H14/$F14 -> 0.70588235 | R14: =I14/F14 -> 0.29411765 | S14: =J14/F14 -> 0.23529412 | T14: =D14/$B14 -> 0.25438596 | U14: =D14/C14 -> 0.74358974 | V14: =E14/C14 -> 0.28205128
A15: Total Analyzed | B15: =SUM(B3:B14) -> 1649 | C15: =SUM(C3:C14) -> 405 | D15: =SUM(D3:D14) -> 308 | E15: =SUM(E3:E14) -> 139 | F15: =SUM(F3:F14) -> 177 | G15: =SUM(G3:G14) -> 137 | H15: =SUM(H3:H14) -> 126 | I15: =SUM(I3:I14) -> 68 | ... K15: =SUM(K3:K14) -> 311 | M15: =F15/$K15 -> 0.56913183 | N15: =G15/$K15 -> 0.44051447 | O15: =H15/$K15 -> 0.40514469 | P15: =G15/$F15 -> 0.7740113 | Q15: =H15/$F15 -> 0.71186441 | R15: =I15/F15 -> 0.38418079 | S15: =J15/F15 -> 0.29378531 | T15: =D15/$B15 -> 0.18677987 | U15: =D15/C15 -> 0.76049383 | V15: =E15/C15 -> 0.34320988

Sheet January
D1: Compliance rubric: | E1: https://docs.google.com/document/d/1vK8DdeN5QbFqKy0h2uLIuuB89hU_Zlj_o41NX1BVtAY/edit?usp=sharing
A2: Article | C2: # Figures | D2: # Appropriate for SBOL Visual | E2: # Compliant with SBOL Visual | F2: Best Practices | G2: SBOL Possible | H2: SBOL Used | I2: SBOL Uniformly Used | J2: Best Practices Used | K2: Best Practices Uniformly Used
A3: Engineered BRET-Based Biologic Light Sources Enable Spatiotemporal Control over Diverse Optogenetic Systems | C3: 4 | D3: 1 | E3: 0 | F3: 0 | G3: =D3>0 -> TRUE | H3: =E3>0 -> FALSE | I3: =AND(G3,(D3=E3)) -> FALSE | J3: =(F3>0) -> FALSE | K3: =AND(I3,(E3=F3)) -> FALSE
A4: Point-of-Use Detection of Environmental Fluoride via a Cell-Free Riboswitch-Based Biosensor | C4: 4 | D4: 3 | E4: 3 | F4: 0 | G4: =D4>0 -> TRUE | H4: =E4>0 -> TRUE | I4: =AND(G4,(D4=E4)) -> TRUE | J4: =(F4>0) -> FALSE | K4: =AND(I4,(E4=F4)) -> FALSE
A5: Design of Mammalian ON-Riboswitches Based on Tandemly Fused Aptamer and Ribozyme | C5: 4 | D5: 1 | E5: 1 | F5: 1 | G5: =D5>0 -> TRUE | H5: =E5>0 -> TRUE | I5: =AND(G5,(D5=E5)) -> TRUE | J5: =(F5>0) -> TRUE | K5: =AND(I5,(E5=F5)) -> TRUE
A6: Host-Informed Expression of CRISPR Guide RNA for Genomic Engineering in Komagataella phaffii | C6: 4 | D6: 2 | E6: 0 | F6: 0 | G6: =D6>0 -> TRUE | H6: =E6>0 -> FALSE | I6: =AND(G6,(D6=E6)) -> FALSE | J6: =(F6>0) -> FALSE | K6: =AND(I6,(E6=F6)) -> FALSE
A7: A Bifunctional Polyphosphate Kinase Driving the Regeneration of Nucleoside Triphosphate and Reconstituted Cell-Free Protein Synthesis | C7: 4 | D7: 0 | E7: 0 | F7: 0 | G7: =D7>0 -> FALSE | H7: =E7>0 -> FALSE | I7: =AND(G7,(D7=E7)) -> FALSE | J7: =(F7>0) -> FALSE | K7: =AND(I7,(E7=F7)) -> FALSE
A8: Evolutionary Outcomes of Diversely Functionalized Aptamers Isolated from in Vitro Evolution | C8: 8 | D8: 0 | E8: 0 | F8: 0 | G8: =D8>0 -> FALSE | H8: =E8>0 -> FALSE | I8: =AND(G8,(D8=E8)) -> FALSE | J8: =(F8>0) -> FALSE | K8: =AND(I8,(E8=F8)) -> FALSE
A9: Identification, Characterization, and Application of a Highly Sensitive Lactam Biosensor from Pseudomonas putida | C9: 5 | D9: 3 | E9: 3 | F9: 0 | G9: =D9>0 -> TRUE | H9: =E9>0 -> TRUE | I9: =AND(G9,(D9=E9)) -> TRUE | J9: =(F9>0) -> FALSE | K9: =AND(I9,(E9=F9)) -> FALSE
A10: Expanding the Natural Products Heterologous Expression Repertoire in the Model Cyanobacterium Anabaena sp. Strain PCC 7120: Production of Pendolmycin and Teleocidin B-4 | C10: 5 | D10: 2 | E10: 0 | F10: 0 | G10: =D10>0 -> TRUE | H10: =E10>0 -> FALSE | I10: =AND(G10,(D10=E10)) -> FALSE | J10: =(F10>0) -> FALSE | K10: =AND(I10,(E10=F10)) -> FALSE
A11: Artificial Cells Capable of Long-Lived Protein Synthesis by Using Aptamer Grafted Polymer Hydrogel | C11: 5 | D11: 1 | E11: 1 | F11: 0 | G11: =D11>0 -> TRUE | H11: =E11>0 -> TRUE | I11: =AND(G11,(D11=E11)) -> TRUE | J11: =(F11>0) -> FALSE | K11: =AND(I11,(E11=F11)) -> FALSE
A12: Design of a Transcriptional Biosensor for the Portable, On-Demand Detection of Cyanuric Acid | C12: 4 | D12: 3 | E12: 3 | F12: 3 | G12: =D12>0 -> TRUE | H12: =E12>0 -> TRUE | I12: =AND(G12,(D12=E12)) -> TRUE | J12: =(F12>0) -> TRUE | K12: =AND(I12,(E12=F12)) -> TRUE
A13: Proteolytic Queues at ClpXP Increase Antibiotic Tolerance | C13: 5 | D13: 0 | E13: 0 | F13: 0 | G13: =D13>0 -> FALSE | H13: =E13>0 -> FALSE | I13: =AND(G13,(D13=E13)) -> FALSE | J13: =(F13>0) -> FALSE | K13: =AND(I13,(E13=F13)) -> FALSE
A14: Multiple-Site Diversification of Regulatory Sequences Enables Interspecies Operability of Genetic Devices | C14: 6 | D14: 3 | E14: 3 | F14: 3 | G14: =D14>0 -> TRUE | H14: =E14>0 -> TRUE | I14: =AND(G14,(D14=E14)) -> TRUE | J14: =(F14>0) -> TRUE | K14: =AND(I14,(E14=F14)) -> TRUE
... A21: mpCRISTAR: Multiple Plasmid Approach for CRISPR/Cas9 and TAR-Mediated Multiplexed Refactoring of Natural Product Biosynthetic Gene Clusters | C21: 2 | D21: 2 | E21: 2 | F21: 0 | G21: =D21>0 -> TRUE | H21: =E21>0 -> TRUE | I21: =AND(G21,(D21=E21)) -> TRUE | J21: =(F21>0) -> FALSE | K21: =AND(I21,(E21=F21)) -> FALSE
B22: Totals: | C22: =SUM(C2:C21) -> 89 | D22: =SUM(D2:D21) -> 31 | E22: =SUM(E2:E21) -> 25 | F22: =SUM(F2:F21) -> 14 | G22: =COUNTIF(G3:G21,"TRUE") -> 14 | H22: =COUNTIF(H3:H21,"TRUE") -> 10 | I22: =COUNTIF(I3:I21,"TRUE") -> 10 | J22: =COUNTIF(J3:J21,"TRUE") -> 5 | K22: =COUNTIF(K3:K21,"TRUE") -> 4 | L22: =COUNTA(E3:E21) -> 19
E23: % of all papers | G23: =G22/L22 -> 0.73684211 | H23: =H22/L22 -> 0.52631579 | I23: =I22/L22 -> 0.52631579 | J23: =J22/L22 -> 0.26315789 | K23: =K22/L22 -> 0.21052632
E24: % of SBOL-possible papers | H24: =H22/G22 -> 0.71428571 | I24: =I22/G22 -> 0.71428571 | J24: =J22/G22 -> 0.35714286 | K24: =K22/G22 -> 0.28571429
E25: % of all / possible figures | G25: =E22/C22 -> 0.28089888 | H25: =E22/D22 -> 0.80645161

Sheet February
D1: Compliance rubric: | E1: https://docs.google.com/document/d/1vK8DdeN5QbFqKy0h2uLIuuB89hU_Zlj_o41NX1BVtAY/edit?usp=sharing
A2: Article | C2: # Figures | D2: # Appropriate for SBOL Visual | E2: # Compliant with SBOL Visual | F2: Best Practices | G2: SBOL Possible | H2: SBOL Used | I2: SBOL Uniformly Used | J2: Best Practices Used | K2: Best Practices Uniformly Used
A3: In Vitro Selection of Peptides and Proteins—Advantages of mRNA Display | C3: 4 | D3: 0 | E3: 0 | F3: 0 | G3: =D3>0 -> FALSE | H3: =E3>0 -> FALSE | I3: =AND(G3,(D3=E3)) -> FALSE | J3: =(F3>0) -> FALSE | K3: =AND(I3,(E3=F3)) -> FALSE
A4: Rational Design of a Bifunctional AND-Gate Ligand To Modulate Cell–Cell Interactions | C4: 5 | D4: 0 | E4: 0 | F4: 0 | G4: =D4>0 -> FALSE | H4: =E4>0 -> FALSE | I4: =AND(G4,(D4=E4)) -> FALSE | J4: =(F4>0) -> FALSE | K4: =AND(I4,(E4=F4)) -> FALSE
A5: Mathematical Models of Protease-Based Enzymatic Biosensors | C5: 6 | D5: 0 | E5: 0 | F5: 0 | G5: =D5>0 -> FALSE | H5: =E5>0 -> FALSE | I5: =AND(G5,(D5=E5)) -> FALSE | J5: =(F5>0) -> FALSE | K5: =AND(I5,(E5=F5)) -> FALSE
A6: Quorum Sensing-Based Dual-Function Switch and Its Application in Solving Two Key Metabolic Engineering Problems | C6: 5 | D6: 3 | E6: 1 | F6: 0 | G6: =D6>0 -> TRUE | H6: =E6>0 -> TRUE | I6: =AND(G6,(D6=E6)) -> FALSE | J6: =(F6>0) -> FALSE | K6: =AND(I6,(E6=F6)) -> FALSE
A7: High-Resolution Scanning of Optimal Biosensor Reporter Promoters in Yeast | C7: 3 | D7: 3 | E7: 3 | F7: 1 | G7: =D7>0 -> TRUE | H7: =E7>0 -> TRUE | I7: =AND(G7,(D7=E7)) -> TRUE | J7: =(F7>0) -> TRUE | K7: =AND(I7,(E7=F7)) -> FALSE
A8: Light-Inducible Recombinases for Bacterial Optogenetics | C8: 4 | D8: 2 | E8: 2 | F8: 0 | G8: =D8>0 -> TRUE | H8: =E8>0 -> TRUE | I8: =AND(G8,(D8=E8)) -> TRUE | J8: =(F8>0) -> FALSE | K8: =AND(I8,(E8=F8)) -> FALSE
A9: Engineering a DNAzyme-Based Operon System for the Production of DNA Nanoscaffolds in Living Bacteria | C9: 3 | D9: 3 | E9: 3 | F9: 2 | G9: =D9>0 -> TRUE | H9: =E9>0 -> TRUE | I9: =AND(G9,(D9=E9)) -> TRUE | J9: =(F9>0) -> TRUE | K9: =AND(I9,(E9=F9)) -> FALSE
A10: Heterologous Production of Lasso Peptide Capistruin in a Burkholderia Host | C10: 4 | D10: 1 | E10: 1 | F10: 1 | G10: =D10>0 -> TRUE | H10: =E10>0 -> TRUE | I10: =AND(G10,(D10=E10)) -> TRUE | J10: =(F10>0) -> TRUE | K10: =AND(I10,(E10=F10)) -> TRUE
A11: Single-Molecule Kinetics Show DNA Pyrimidine Content Strongly Affects RNA:DNA and TNA:DNA Heteroduplex Dissociation Rates | C11: 3 | D11: 0 | E11: 0 | F11: 0 | G11: =D11>0 -> FALSE | H11: =E11>0 -> FALSE | I11: =AND(G11,(D11=E11)) -> FALSE | J11: =(F11>0) -> FALSE | K11: =AND(I11,(E11=F11)) -> FALSE
A12: Hyperstable De Novo Protein with a Dimeric Bisecting Topology | C12: 4 | D12: 0 | E12: 0 | F12: 0 | G12: =D12>0 -> FALSE | H12: =E12>0 -> FALSE | I12: =AND(G12,(D12=E12)) -> FALSE | J12: =(F12>0) -> FALSE | K12: =AND(I12,(E12=F12)) -> FALSE
A13: Malic Enzyme Facilitates d-Lactate Production through Increased Pyruvate Supply during Anoxic Dark Fermentation in Synechocystis sp. PCC 6803 | C13: 6 | D13: 0 | E13: 0 | F13: 0 | G13: =D13>0 -> FALSE | H13: =E13>0 -> FALSE | I13: =AND(G13,(D13=E13)) -> FALSE | J13: =(F13>0) -> FALSE | K13: =AND(I13,(E13=F13)) -> FALSE
A14: Daisy Chain Topology Based Mammalian Synthetic Circuits for RNA-Only Delivery | C14: 12 | D14: 9 | E14: 9 | F14: 9 | G14: =D14>0 -> TRUE | H14: =E14>0 -> TRUE | I14: =AND(G14,(D14=E14)) -> TRUE | J14: =(F14>0) -> TRUE | K14: =AND(I14,(E14=F14)) -> TRUE
... A30: Promoter Screening Facilitates Heterologous Production of Complex Secondary Metabolites in Burkholderiales Strains | C30: 2 | D30: 0 | E30: 0 | F30: 0 | G30: =D30>0 -> FALSE | H30: =E30>0 -> FALSE | I30: =AND(G30,(D30=E30)) -> FALSE | J30: =(F30>0) -> FALSE | K30: =AND(I30,(E30=F30)) -> FALSE
B31: Totals: | C31: =SUM(C2:C30) -> 152 | D31: =SUM(D2:D30) -> 37 | E31: =SUM(E2:E30) -> 34 | F31: =SUM(F2:F30) -> 25 | G31: =COUNTIF(G3:G30,"TRUE") -> 15 | H31: =COUNTIF(H3:H30,"TRUE") -> 14 | I31: =COUNTIF(I3:I30,"TRUE") -> 13 | J31: =COUNTIF(J3:J30,"TRUE") -> 11 | K31: =COUNTIF(K3:K30,"TRUE") -> 7 | L31: =COUNTA(E3:E30) -> 28
E32: % of all papers | G32: =G31/L31 -> 0.53571429 | H32: =H31/L31 -> 0.5 | I32: =I31/L31 -> 0.46428571 | J32: =J31/L31 -> 0.39285714 | K32: =K31/L31 -> 0.25
E33: % of SBOL-possible papers | H33: =H31/G31 -> 0.93333333 | I33: =I31/G31 -> 0.86666667 | J33: =J31/G31 -> 0.73333333 | K33: =K31/G31 -> 0.46666667
E34: % of all / possible figures | G34: =E31/C31 -> 0.22368421 | H34: =E31/D31 -> 0.91891892

Sheet March
D1: Compliance rubric: | E1: https://docs.google.com/document/d/1vK8DdeN5QbFqKy0h2uLIuuB89hU_Zlj_o41NX1BVtAY/edit?usp=sharing
A2: Article | C2: # Figures | D2: # Appropriate for SBOL Visual | E2: # Compliant with SBOL Visual | F2: Best Practices | G2: SBOL Possible | H2: SBOL Used | I2: SBOL Uniformly Used | J2: Best Practices Used | K2: Best Practices Uniformly Used
A3: Site-Specific Post-translational Surface Modification of Adeno-Associated Virus Vectors Using Leucine Zippers | C3: 4 | D3: 1 | E3: 1 | F3: 1 | G3: =D3>0 -> TRUE | H3: =E3>0 -> TRUE | I3: =AND(G3,(D3=E3)) -> TRUE | J3: =(F3>0) -> TRUE | K3: =AND(I3,(E3=F3)) -> TRUE
A4: Adenosine Triphosphate and Carbon Efficient Route to Second Generation Biofuel Isopentanol | C4: 4 | D4: 1 | E4: 1 | F4: 0 | G4: =D4>0 -> TRUE | H4: =E4>0 -> TRUE | I4: =AND(G4,(D4=E4)) -> TRUE | J4: =(F4>0) -> FALSE | K4: =AND(I4,(E4=F4)) -> FALSE
A5: Engineered Living Materials Based on Adhesin-Mediated Trapping of Programmable Cells | C5: 4 | D5: 0 | E5: 0 | F5: 0 | G5: =D5>0 -> FALSE | H5: =E5>0 -> FALSE | I5: =AND(G5,(D5=E5)) -> FALSE | J5: =(F5>0) -> FALSE | K5: =AND(I5,(E5=F5)) -> FALSE
A6: Genetic Code Expansion, Protein Expression, and Protein Functionalization in Bacillus subtilis | C6: 6 | D6: 4 | E6: 4 | F6: 0 | G6: =D6>0 -> TRUE | H6: =E6>0 -> TRUE | I6: =AND(G6,(D6=E6)) -> TRUE | J6: =(F6>0) -> FALSE | K6: =AND(I6,(E6=F6)) -> FALSE
A7: Directed Metabolic Pathway Evolution Enables Functional Pterin-Dependent Aromatic-Amino-Acid Hydroxylation in Escherichia coli | C7: 4 | D7: 0 | E7: 0 | F7: 0 | G7: =D7>0 -> FALSE | H7: =E7>0 -> FALSE | I7: =AND(G7,(D7=E7)) -> FALSE | J7: =(F7>0) -> FALSE | K7: =AND(I7,(E7=F7)) -> FALSE
A8: SPLIT: Stable Protein Coacervation Using a Light Induced Transition | C8: 6 | D8: 1 | E8: 1 | F8: 0 | G8: =D8>0 -> TRUE | H8: =E8>0 -> TRUE | I8: =AND(G8,(D8=E8)) -> TRUE | J8: =(F8>0) -> FALSE | K8: =AND(I8,(E8=F8)) -> FALSE
A9: Yeast Surface Display System for Facilitated Production and Application of Phage Endolysin | C9: 6 | D9: 1 | E9: 0 | F9: 0 | G9: =D9>0 -> TRUE | H9: =E9>0 -> FALSE | I9: =AND(G9,(D9=E9)) -> FALSE | J9: =(F9>0) -> FALSE | K9: =AND(I9,(E9=F9)) -> FALSE
A10: Design and Characterization of an Icosahedral Protein Cage Formed by a Double-Fusion Protein Containing Three Distinct Symmetry Elements | C10: 3 | D10: 0 | E10: 0 | F10: 0 | G10: =D10>0 -> FALSE | H10: =E10>0 -> FALSE | I10: =AND(G10,(D10=E10)) -> FALSE | J10: =(F10>0) -> FALSE | K10: =AND(I10,(E10=F10)) -> FALSE
A11: Highly Efficient Biosynthesis of Hypoxanthine in Escherichia coli and Transcriptome-Based Analysis of the Purine Metabolism | C11: 6 | D11: 0 | E11: 0 | F11: 0 | G11: =D11>0 -> FALSE | H11: =E11>0 -> FALSE | I11: =AND(G11,(D11=E11)) -> FALSE | J11: =(F11>0) -> FALSE | K11: =AND(I11,(E11=F11)) -> FALSE
A12: Linking Engineered Cells to Their Digital Twins: A Version Control System for Strain Engineering | C12: 5 | D12: 1 | E12: 1 | F12: 0 | G12: =D12>0 -> TRUE | H12: =E12>0 -> TRUE | I12: =AND(G12,(D12=E12)) -> TRUE | J12: =(F12>0) -> FALSE | K12: =AND(I12,(E12=F12)) -> FALSE
A13: Mitochondrial Compartmentalization Confers Specificity to the 2-Ketoacid Recursive Pathway: Increasing Isopentanol Production in Saccharomyces cerevisiae | C13: 4 | D13: 0 | E13: 0 | F13: 0 | G13: =D13>0 -> FALSE | H13: =E13>0 -> FALSE | I13: =AND(G13,(D13=E13)) -> FALSE | J13: =(F13>0) -> FALSE | K13: =AND(I13,(E13=F13)) -> FALSE
A14: MEMO: A Method for Computing Metabolic Modules for Cell-Free Production Systems | C14: 4 | D14: 0 | E14: 0 | F14: 0 | G14: =D14>0 -> FALSE | H14: =E14>0 -> FALSE | I14: =AND(G14,(D14=E14)) -> FALSE | J14: =(F14>0) -> FALSE | K14: =AND(I14,(E14=F14)) -> FALSE
... A25: Expanding the CRISPR Toolbox in Culicine Mosquitoes: In Vitro Validation of Pol III Promoters | C25: 3 | D25: 1 | E25: 1 | F25: 1 | G25: =D25>0 -> TRUE | H25: =E25>0 -> TRUE | I25: =AND(G25,(D25=E25)) -> TRUE | J25: =(F25>0) -> TRUE | K25: =AND(I25,(E25=F25)) -> TRUE
B26: Totals: | C26: =SUM(C2:C25) -> 120 | D26: =SUM(D2:D25) -> 23 | E26: =SUM(E2:E25) -> 21 | F26: =SUM(F2:F25) -> 7 | G26: =COUNTIF(G3:G25,"TRUE") -> 12 | H26: =COUNTIF(H3:H25,"TRUE") -> 10 | I26: =COUNTIF(I3:I25,"TRUE") -> 10 | J26: =COUNTIF(J3:J25,"TRUE") -> 5 | K26: =COUNTIF(K3:K25,"TRUE") -> 4 | L26: =COUNTA(E3:E25) -> 23
E27: % of all papers | G27: =G26/L26 -> 0.52173913 | H27: =H26/L26 -> 0.43478261 | I27: =I26/L26 -> 0.43478261 | J27: =J26/L26 -> 0.2173913 | K27: =K26/L26 -> 0.17391304
E28: % of SBOL-possible papers | H28: =H26/G26 -> 0.83333333 | I28: =I26/G26 -> 0.83333333 | J28: =J26/G26 -> 0.41666667 | K28: =K26/G26 -> 0.33333333
E29: % of all / possible figures | G29: =E26/C26 -> 0.175 | H29: =E26/D26 -> 0.91304348

Sheet April
D1: Compliance rubric: | E1: https://docs.google.com/document/d/1vK8DdeN5QbFqKy0h2uLIuuB89hU_Zlj_o41NX1BVtAY/edit?usp=sharing
A2: Article | C2: # Figures | D2: # Appropriate for SBOL Visual | E2: # Compliant with SBOL Visual | F2: Best Practices | G2: SBOL Possible | H2: SBOL Used | I2: SBOL Uniformly Used | J2: Best Practices Used | K2: Best Practices Uniformly Used
A3: The Theophylline Aptamer: 25 Years as an Important Tool in Cellular Engineering Research | C3: 5 | D3: 0 | E3: 0 | F3: 0 | G3: =D3>0 -> FALSE | H3: =E3>0 -> FALSE | I3: =AND(G3,(D3=E3)) -> FALSE | J3: =(F3>0) -> FALSE | K3: =AND(I3,(E3=F3)) -> FALSE
A4: A New Biosensor for Stilbenes and a Cannabinoid Enabled by Genome Mining of a Transcriptional Regulator | C4: 5 | D4: 3 | E4: 3 | F4: 1 | G4: =D4>0 -> TRUE | H4: =E4>0 -> TRUE | I4: =AND(G4,(D4=E4)) -> TRUE | J4: =(F4>0) -> TRUE | K4: =AND(I4,(E4=F4)) -> FALSE
A5: Modulating Pathway Performance by Perturbing Local Genetic Context | C5: 7 | D5: 1 | E5: 0 | F5: 0 | G5: =D5>0 -> TRUE | H5: =E5>0 -> FALSE | I5: =AND(G5,(D5=E5)) -> FALSE | J5: =(F5>0) -> FALSE | K5: =AND(I5,(E5=F5)) -> FALSE
A6: Fully Productive Cell-Free Genetic Code Expansion by Structure-Based Engineering of Methanomethylophilus alvus Pyrrolysyl-tRNA Synthetase | C6: 8 | D6: 0 | E6: 0 | F6: 0 | G6: =D6>0 -> FALSE | H6: =E6>0 -> FALSE | I6: =AND(G6,(D6=E6)) -> FALSE | J6: =(F6>0) -> FALSE | K6: =AND(I6,(E6=F6)) -> FALSE
A7: Mutations in a Single Signaling Pathway Allow Cell Growth in Heavy Water | C7: 6 | D7: 0 | E7: 0 | F7: 0 | G7: =D7>0 -> FALSE | H7: =E7>0 -> FALSE | I7: =AND(G7,(D7=E7)) -> FALSE | J7: =(F7>0) -> FALSE | K7: =AND(I7,(E7=F7)) -> FALSE
A8: Programming the Sequential Release of DNA | C8: 5 | D8: 0 | E8: 0 | F8: 0 | G8: =D8>0 -> FALSE | H8: =E8>0 -> FALSE | I8: =AND(G8,(D8=E8)) -> FALSE | J8: =(F8>0) -> FALSE | K8: =AND(I8,(E8=F8)) -> FALSE
A9: De Novo Biosynthesis of Caffeic Acid from Glucose by Engineered Saccharomyces cerevisiae | C9: 6 | D9: 0 | E9: 0 | F9: 0 | G9: =D9>0 -> FALSE | H9: =E9>0 -> FALSE | I9: =AND(G9,(D9=E9)) -> FALSE | J9: =(F9>0) -> FALSE | K9: =AND(I9,(E9=F9)) -> FALSE
A10: Unlocking Applications of Cell-Free Biotechnology through Enhanced Shelf Life and Productivity of E. coli Extracts | C10: 5 | D10: 0 | E10: 0 | F10: 0 | G10: =D10>0 -> FALSE | H10: =E10>0 -> FALSE | I10: =AND(G10,(D10=E10)) -> FALSE | J10: =(F10>0) -> FALSE | K10: =AND(I10,(E10=F10)) -> FALSE
A11: Population Dynamics of Underdominance Gene Drive Systems in Continuous Space | C11: 8 | D11: 0 | E11: 0 | F11: 0 | G11: =D11>0 -> FALSE | H11: =E11>0 -> FALSE | I11: =AND(G11,(D11=E11)) -> FALSE | J11: =(F11>0) -> FALSE | K11: =AND(I11,(E11=F11)) -> FALSE
A12: Balancing Cell Populations Endowed with a Synthetic Toggle Switch via Adaptive Pulsatile Feedback Control | C12: 7 | D12: 1 | E12: 1 | F12: 0 | G12: =D12>0 -> TRUE | H12: =E12>0 -> TRUE | I12: =AND(G12,(D12=E12)) -> TRUE | J12: =(F12>0) -> FALSE | K12: =AND(I12,(E12=F12)) -> FALSE
A13: A Self-Replicating Linear DNA | C13: 6 | D13: 0 | E13: 0 | F13: 0 | G13: =D13>0 -> FALSE | H13: =E13>0 -> FALSE | I13: =AND(G13,(D13=E13)) -> FALSE | J13: =(F13>0) -> FALSE | K13: =AND(I13,(E13=F13)) -> FALSE
A14: Automatic Redirection of Carbon Flux between Glycolysis and Pentose Phosphate Pathway Using an Oxygen-Responsive Metabolic Switch in Corynebacterium glutamicum | C14: 6 | D14: 0 | E14: 0 | F14: 0 | G14: =D14>0 -> FALSE | H14: =E14>0 -> FALSE | I14: =AND(G14,(D14=E14)) -> FALSE | J14: =(F14>0) -> FALSE | K14: =AND(I14,(E14=F14)) -> FALSE
... A28: SBOL Visual 2 Ontology | C28: 3 | D28: 3 | E28: 3 | F28: 3 | G28: =D28>0 -> TRUE | H28: =E28>0 -> TRUE | I28: =AND(G28,(D28=E28)) -> TRUE | J28: =(F28>0) -> TRUE | K28: =AND(I28,(E28=F28)) -> TRUE
B29: Totals: | C29: =SUM(C2:C28) -> 151 | D29: =SUM(D2:D28) -> 28 | E29: =SUM(E2:E28) -> 24 | F29: =SUM(F2:F28) -> 13 | G29: =COUNTIF(G3:G28,"TRUE") -> 11 | H29: =COUNTIF(H3:H28,"TRUE") -> 9 | I29: =COUNTIF(I3:I28,"TRUE") -> 7 | J29: =COUNTIF(J3:J28,"TRUE") -> 5 | K29: =COUNTIF(K3:K28,"TRUE") -> 3 | L29: =COUNTA(E3:E28) -> 26
E30: % of all papers | G30: =G29/L29 -> 0.42307692 | H30: =H29/L29 -> 0.34615385 | I30: =I29/L29 -> 0.26923077 | J30: =J29/L29 -> 0.19230769 | K30: =K29/L29 -> 0.11538462
E31: % of SBOL-possible papers | H31: =H29/G29 -> 0.81818182 | I31: =I29/G29 -> 0.63636364 | J31: =J29/G29 -> 0.45454545 | K31: =K29/G29 -> 0.27272727
E32: % of all / possible figures | G32: =E29/C29 -> 0.1589404 | H32: =E29/D29 -> 0.85714286

Sheet May
D1: Compliance rubric: | E1: https://docs.google.com/document/d/1vK8DdeN5QbFqKy0h2uLIuuB89hU_Zlj_o41NX1BVtAY/edit?usp=sharing
A2: Article | C2: # Figures | D2: # Appropriate for SBOL Visual | E2: # Compliant with SBOL Visual | F2: Best Practices | G2: SBOL Possible | H2: SBOL Used | I2: SBOL Uniformly Used | J2: Best Practices Used | K2: Best Practices Uniformly Used
A3: Analyzing and Engineering the Product Selectivity of a 2-Methylenebornane Synthase | C3: 4 | D3: 0 | E3: 0 | F3: 0 | G3: =D3>0 -> FALSE | H3: =E3>0 -> FALSE | I3: =AND(G3,(D3=E3)) -> FALSE | J3: =(F3>0) -> FALSE | K3: =AND(I3,(E3=F3)) -> FALSE
A4: A Chemical Switch System to Modulate Chimeric Antigen Receptor T Cell Activity through Proteolysis-Targeting Chimaera Technology | C4: 4 | D4: 0 | E4: 0 | F4: 0 | G4: =D4>0 -> FALSE | H4: =E4>0 -> FALSE | I4: =AND(G4,(D4=E4)) -> FALSE | J4: =(F4>0) -> FALSE | K4: =AND(I4,(E4=F4)) -> FALSE
A5: A Modular Method for Directing Protein Self-Assembly | C5: 4 | D5: 0 | E5: 0 | F5: 0 | G5: =D5>0 -> FALSE | H5: =E5>0 -> FALSE | I5: =AND(G5,(D5=E5)) -> FALSE | J5: =(F5>0) -> FALSE | K5: =AND(I5,(E5=F5)) -> FALSE
A6: Multiplex Generation, Tracking, and Functional Screening of Substitution Mutants Using a CRISPR/Retron System | C6: 4 | D6: 3 | E6: 3 | F6: 3 | G6: =D6>0 -> TRUE | H6: =E6>0 -> TRUE | I6: =AND(G6,(D6=E6)) -> TRUE | J6: =(F6>0) -> TRUE | K6: =AND(I6,(E6=F6)) -> TRUE
A7: Transcript Barcoding Illuminates the Expression Level of Synthetic Constructs in E. coli Nissle Residing in the Mammalian Gut | C7: 5 | D7: 1 | E7: 0 | F7: 0 | G7: =D7>0 -> TRUE | H7: =E7>0 -> FALSE | I7: =AND(G7,(D7=E7)) -> FALSE | J7: =(F7>0) -> FALSE | K7: =AND(I7,(E7=F7)) -> FALSE
A8: Engineering Prokaryotic Transcriptional Activator XylR as a Xylose-Inducible Biosensor for Transcription Activation in Yeast | C8: 5 | D8: 4 | E8: 0 | F8: 0 | G8: =D8>0 -> TRUE | H8: =E8>0 -> FALSE | I8: =AND(G8,(D8=E8)) -> FALSE | J8: =(F8>0) -> FALSE | K8: =AND(I8,(E8=F8)) -> FALSE
A9: Genome-Wide CRISPRi-Based Identification of Targets for Decoupling Growth from Production | C9: 4 | D9: 0 | E9: 0 | F9: 0 | G9: =D9>0 -> FALSE | H9: =E9>0 -> FALSE | I9: =AND(G9,(D9=E9)) -> FALSE | J9: =(F9>0) -> FALSE | K9: =AND(I9,(E9=F9)) -> FALSE
A10: A Synthetic Genetic Circuit Enables Precise Quantification of Direct Repeat Deletion in Bacteria | C10: 6 | D10: 2 | E10: 2 | F10: 0 | G10: =D10>0 -> TRUE | H10: =E10>0 -> TRUE | I10: =AND(G10,(D10=E10)) -> TRUE | J10: =(F10>0) -> FALSE | K10: =AND(I10,(E10=F10)) -> FALSE
A11: Facilitating Protein Expression with Portable 5′-UTR Secondary Structures in Bacillus licheniformis | C11: 7 | D11: 0 | E11: 0 | F11: 0 | G11: =D11>0 -> FALSE | H11: =E11>0 -> FALSE | I11: =AND(G11,(D11=E11)) -> FALSE | J11: =(F11>0) -> FALSE | K11: =AND(I11,(E11=F11)) -> FALSE
A12: A Synthetic Malonyl-CoA Metabolic Oscillator in Komagataella phaffii | C12: 4 | D12: 4 | E12: 4 | F12: 4 | G12: =D12>0 -> TRUE | H12: =E12>0 -> TRUE | I12: =AND(G12,(D12=E12)) -> TRUE | J12: =(F12>0) -> TRUE | K12: =AND(I12,(E12=F12)) -> TRUE
A13: MAPPS: A Web-Based Tool for Metabolic Pathway Prediction and Network Analysis in the Postgenomic Era | C13: 5 | D13: 0 | E13: 0 | F13: 0 | G13: =D13>0 -> FALSE | H13: =E13>0 -> FALSE | I13: =AND(G13,(D13=E13)) -> FALSE | J13: =(F13>0) -> FALSE | K13: =AND(I13,(E13=F13)) -> FALSE
A14: Determinants for Efficient Editing with Cas9-Mediated Recombineering in Escherichia coli | C14: 7 | D14: 2 | E14: 2 | F14: 1 | G14: =D14>0 -> TRUE | H14: =E14>0 -> TRUE | I14: =AND(G14,(D14=E14)) -> TRUE | J14: =(F14>0) -> TRUE | K14: =AND(I14,(E14=F14)) -> FALSE
... A26: Translation Related Factors Improve the Productivity of a Streptomyces-Based Cell-Free Protein Synthesis System | C26: 2 | D26: 0 | E26: 0 | F26: 0 | G26: =D26>0 -> FALSE | H26: =E26>0 -> FALSE | I26: =AND(G26,(D26=E26)) -> FALSE | J26: =(F26>0) -> FALSE | K26: =AND(I26,(E26=F26)) -> FALSE
B27: Totals: | C27: =SUM(C2:C26) -> 125 | D27: =SUM(D2:D26) -> 31 | E27: =SUM(E2:E26) -> 22 | F27: =SUM(F2:F26) -> 13 | G27: =COUNTIF(G3:G26,"TRUE") -> 14 | H27: =COUNTIF(H3:H26,"TRUE") -> 8 | I27: =COUNTIF(I3:I26,"TRUE") -> 8 | J27: =COUNTIF(J3:J26,"TRUE") -> 6 | K27: =COUNTIF(K3:K26,"TRUE") -> 3 | L27: =COUNTA(E3:E26) -> 24
E28: % of all papers | G28: =G27/L27 -> 0.58333333 | H28: =H27/L27 -> 0.33333333 | I28: =I27/L27 -> 0.33333333 | J28: =J27/L27 -> 0.25 | K28: =K27/L27 -> 0.125
E29: % of SBOL-possible papers | H29: =H27/G27 -> 0.57142857 | I29: =I27/G27 -> 0.57142857 | J29: =J27/G27 -> 0.42857143 | K29: =K27/G27 -> 0.21428571
E30: % of all / possible figures | G30: =E27/C27 -> 0.176 | H30: =E27/D27 -> 0.70967742

Sheet June
D1: Compliance rubric: | E1: https://docs.google.com/document/d/1vK8DdeN5QbFqKy0h2uLIuuB89hU_Zlj_o41NX1BVtAY/edit?usp=sharing
A2: Article | C2: # Figures | D2: # Appropriate for SBOL Visual | E2: # Compliant with SBOL Visual | F2: Best Practices | G2: SBOL Possible | H2: SBOL Used | I2: SBOL Uniformly Used | J2: Best Practices Used | K2: Best Practices Uniformly Used
A3: Nucleic Acid Detection Using CRISPR/Cas Biosensing Technologies | C3: 4 | D3: 0 | E3: 0 | F3: 0 | G3: =D3>0 -> FALSE | H3: =E3>0 -> FALSE | I3: =AND(G3,(D3=E3)) -> FALSE | J3: =(F3>0) -> FALSE | K3: =AND(I3,(E3=F3)) -> FALSE
A4: Smart Microbial Cells Couple Catalysis and Sensing to Provide High-Throughput Selection of an Organophosphate Hydrolase | C4: 4 | D4: 1 | E4: 0 | F4: 0 | G4: =D4>0 -> TRUE | H4: =E4>0 -> FALSE | I4: =AND(G4,(D4=E4)) -> FALSE | J4: =(F4>0) -> FALSE | K4: =AND(I4,(E4=F4)) -> FALSE
A5: Microbial Synthesis of Human-Hormone Melatonin at Gram Scales | C5: 3 | D5: 1 | E5: 1 | F5: 0 | G5: =D5>0 -> TRUE | H5: =E5>0 -> TRUE | I5: =AND(G5,(D5=E5)) -> TRUE | J5: =(F5>0) -> FALSE | K5: =AND(I5,(E5=F5)) -> FALSE
A6: Functional Identification of Two Types of Carotene Hydroxylases from the Green Alga Dunaliella bardawil Rich in Lutein | C6: 5 | D6: 0 | E6: 0 | F6: 0 | G6: =D6>0 -> FALSE | H6: =E6>0 -> FALSE | I6: =AND(G6,(D6=E6)) -> FALSE | J6: =(F6>0) -> FALSE | K6: =AND(I6,(E6=F6)) -> FALSE
A7: Turning the Screw: Engineering Extreme pH Resistance in Escherichia coli through Combinatorial Synthetic Operons | C7: 4 | D7: 3 | E7: 2 | F7: 2 | G7: =D7>0 -> TRUE | H7: =E7>0 -> TRUE | I7: =AND(G7,(D7=E7)) -> FALSE | J7: =(F7>0) -> TRUE | K7: =AND(I7,(E7=F7)) -> FALSE
A8: Comprehensive Analysis of Genomic Safe Harbors as Target Sites for Stable Expression of the Heterologous Gene in HEK293 Cells | C8: 4 | D8: 2 | E8: 2 | F8: 0 | G8: =D8>0 -> TRUE | H8: =E8>0 -> TRUE | I8: =AND(G8,(D8=E8)) -> TRUE | J8: =(F8>0) -> FALSE | K8: =AND(I8,(E8=F8)) -> FALSE
A9: Automated Continuous Evolution of Proteins in Vivo | C9: 3 | D9: 0 | E9: 0 | F9: 0 | G9: =D9>0 -> FALSE | H9: =E9>0 -> FALSE | I9: =AND(G9,(D9=E9)) -> FALSE | J9: =(F9>0) -> FALSE | K9: =AND(I9,(E9=F9)) -> FALSE
A10: Pattern Engineering of Living Bacterial Colonies Using Meniscus-Driven Fluidic Channels | C10: 4 | D10: 0 | E10: 0 | F10: 0 | G10: =D10>0 -> FALSE | H10: =E10>0 -> FALSE | I10: =AND(G10,(D10=E10)) -> FALSE | J10: =(F10>0) -> FALSE | K10: =AND(I10,(E10=F10)) -> FALSE
A11: Dynamic Cell Programming with Quorum Sensing-Controlled CRISPRi Circuit | C11: 3 | D11: 3 | E11: 3 | F11: 0 | G11: =D11>0 -> TRUE | H11: =E11>0 -> TRUE | I11: =AND(G11,(D11=E11)) -> TRUE | J11: =(F11>0) -> FALSE | K11: =AND(I11,(E11=F11)) -> FALSE
A12: A Small-Molecule-Responsive Riboswitch Enables Conditional Induction of Viral Vector-Mediated Gene Expression in Mice | C12: 7 | D12: 5 | E12: 5 | F12: 0 | G12: =D12>0 -> TRUE | H12: =E12>0 -> TRUE | I12: =AND(G12,(D12=E12)) -> TRUE | J12: =(F12>0) -> FALSE | K12: =AND(I12,(E12=F12)) -> FALSE
A13: Caged Activators of Artificial Allosteric Protein Biosensors | C13: 5 | D13: 0 | E13: 0 | F13: 0 | G13: =D13>0 -> FALSE | H13: =E13>0 -> FALSE | I13: =AND(G13,(D13=E13)) -> FALSE | J13: =(F13>0) -> FALSE | K13: =AND(I13,(E13=F13)) -> FALSE
A14: Overcoming the Challenges of Megabase-Sized Plasmid Construction in Escherichia coli | C14: 5 | D14: 4 | E14: 3 | F14: 0 | G14: =D14>0 -> TRUE | H14: =E14>0 -> TRUE | I14: =AND(G14,(D14=E14)) -> FALSE | J14: =(F14>0) -> FALSE | K14: =AND(I14,(E14=F14)) -> FALSE
... A30: Media Robustness and Scalability of Phosphate Regulated Promoters Useful for Two-Stage Autoinduction in E. coli | C30: 2 | D30: 1 | E30: 1 | F30: 0 | G30: =D30>0 -> TRUE | H30: =E30>0 -> TRUE | I30: =AND(G30,(D30=E30)) -> TRUE | J30: =(F30>0) -> FALSE | K30: =AND(I30,(E30=F30)) -> FALSE
B31: Totals: | C31: =SUM(C2:C30) -> 129 | D31: =SUM(D2:D30) -> 37 | E31: =SUM(E2:E30) -> 30 | F31: =SUM(F2:F30) -> 8 | G31: =COUNTIF(G3:G30,"TRUE") -> 16 | H31: =COUNTIF(H3:H30,"TRUE") -> 13 | I31: =COUNTIF(I3:I30,"TRUE") -> 11 | J31: =COUNTIF(J3:J30,"TRUE") -> 4 | K31: =COUNTIF(K3:K30,"TRUE") -> 3 | L31: =COUNTA(E3:E30) -> 28
E32: % of all papers | G32: =G31/L31 -> 0.57142857 | H32: =H31/L31 -> 0.46428571 | I32: =I31/L31 -> 0.39285714 | J32: =J31/L31 -> 0.14285714 | K32: =K31/L31 -> 0.10714286
E33: % of SBOL-possible papers | H33: =H31/G31 -> 0.8125 | I33: =I31/G31 -> 0.6875 | J33: =J31/G31 -> 0.25 | K33: =K31/G31 -> 0.1875
E34: % of all / possible figures | G34: =E31/C31 -> 0.23255814 | H34: =E31/D31 -> 0.81081081

Sheet July
D1: Compliance rubric: | E1: https://docs.google.com/document/d/1vK8DdeN5QbFqKy0h2uLIuuB89hU_Zlj_o41NX1BVtAY/edit?usp=sharing
A2: Article | C2: # Figures | D2: # Appropriate for SBOL Visual | E2: # Compliant with SBOL Visual | F2: Best Practices | G2: SBOL Possible | H2: SBOL Used | I2: SBOL Uniformly Used | J2: Best Practices Used | K2: Best Practices Uniformly Used
A3: Processing DNA-Based Molecular Signals into Graphical Displays | C3: 4 | D3: 0 | E3: 0 | F3: 0 | G3: =D3>0 -> FALSE | H3: =E3>0 -> FALSE | I3: =AND(G3,(D3=E3)) -> FALSE | J3: =(F3>0) -> FALSE | K3: =AND(I3,(E3=F3)) -> FALSE
A4: Domain-Specific Programming Languages for Computational Nucleic Acid Systems | C4: 12 | D4: 0 | E4: 0 | F4: 0 | G4: =D4>0 -> FALSE | H4: =E4>0 -> FALSE | I4: =AND(G4,(D4=E4)) -> FALSE | J4: =(F4>0) -> FALSE | K4: =AND(I4,(E4=F4)) -> FALSE
A5: Biosystems Design by Machine Learning | C5: 8 | D5: 0 | E5: 0 | F5: 0 | G5: =D5>0 -> FALSE | H5: =E5>0 -> FALSE | I5: =AND(G5,(D5=E5)) -> FALSE | J5: =(F5>0) -> FALSE | K5: =AND(I5,(E5=F5)) -> FALSE
A6: Synthetic Glycobiology: Parts, Systems, and Applications | C6: 5 | D6: 0 | E6: 0 | F6: 0 | G6: =D6>0 -> FALSE | H6: =E6>0 -> FALSE | I6: =AND(G6,(D6=E6)) -> FALSE | J6: =(F6>0) -> FALSE | K6: =AND(I6,(E6=F6)) -> FALSE
A7: Synthesis Success Calculator: Predicting the Rapid Synthesis of DNA Fragments with Machine Learning | C7: 4 | D7: 0 | E7: 0 | F7: 0 | G7: =D7>0 -> FALSE | H7: =E7>0 -> FALSE | I7: =AND(G7,(D7=E7)) -> FALSE | J7: =(F7>0) -> FALSE | K7: =AND(I7,(E7=F7)) -> FALSE
A8: Endogenous p21-Dependent Transgene Control for CHO Cell Engineering | C8: 4 | D8: 0 | E8: 0 | F8: 0 | G8: =D8>0 -> FALSE | H8: =E8>0 -> FALSE | I8: =AND(G8,(D8=E8)) -> FALSE | J8: =(F8>0) -> FALSE | K8: =AND(I8,(E8=F8)) -> FALSE
A9: Assessment of Robustness to Temperature in a Negative Feedback Loop and a Feedforward Loop | C9: 6 | D9: 2 | E9: 2 | F9: 0 | G9: =D9>0 -> TRUE | H9: =E9>0 -> TRUE | I9: =AND(G9,(D9=E9)) -> TRUE | J9: =(F9>0) -> FALSE | K9: =AND(I9,(E9=F9)) -> FALSE
A10: Purification of an Intact Human Protein Overexpressed from Its Endogenous Locus via Direct Genome Engineering | C10: 3 | D10: 1 | E10: 1 | F10: 0 | G10: =D10>0 -> TRUE | H10: =E10>0 -> TRUE | I10: =AND(G10,(D10=E10)) -> TRUE | J10: =(F10>0) -> FALSE | K10: =AND(I10,(E10=F10)) -> FALSE
A11: Rational Design and Self-Assembly of Coiled-Coil Linked SasG Protein Fibrils | C11: 5 | D11: 0 | E11: 0 | F11: 0 | G11: =D11>0 -> FALSE | H11: =E11>0 -> FALSE | I11: =AND(G11,(D11=E11)) -> FALSE | J11: =(F11>0) -> FALSE | K11: =AND(I11,(E11=F11)) -> FALSE
A12: Preparation of a Millimeter-Sized Supergiant Liposome That Allows for Efficient, Eukaryotic Cell-Free Translation in the Interior by Spontaneous Emulsion Transfer | C12: 4 | D12: 0 | E12: 0 | F12: 0 | G12: =D12>0 -> FALSE | H12: =E12>0 -> FALSE | I12: =AND(G12,(D12=E12)) -> FALSE | J12: =(F12>0) -> FALSE | K12: =AND(I12,(E12=F12)) -> FALSE
A13: Optimal Ratio of Carbon Flux between Glycolysis and the Pentose Phosphate Pathway for Amino Acid Accumulation in Corynebacterium glutamicum | C13: 3 | D13: 0 | E13: 0 | F13: 0 | G13: =D13>0 -> FALSE | H13: =E13>0 -> FALSE | I13: =AND(G13,(D13=E13)) -> FALSE | J13: =(F13>0) -> FALSE | K13: =AND(I13,(E13=F13)) -> FALSE
A14: Artificial Protein-Responsive Riboswitches Upregulate Non-AUG Translation Initiation in Yeast | C14: 6 | D14: 6 | E14: 6 | F14: 0 | G14: =D14>0 -> TRUE | H14: =E14>0 -> TRUE | I14: =AND(G14,(D14=E14)) -> TRUE | J14: =(F14>0) -> FALSE | K14: =AND(I14,(E14=F14)) -> FALSE
... A41: Targeted Diversification in the S. cerevisiae Genome with CRISPR-Guided DNA Polymerase I | C41: 2 | D41: 0 | E41: 0 | F41: 0 | G41: =D41>0 -> FALSE | H41: =E41>0 -> FALSE | I41: =AND(G41,(D41=E41)) -> FALSE | J41: =(F41>0) -> FALSE | K41: =AND(I41,(E41=F41)) -> FALSE
A42: Site-Directed Mutagenesis of Large Biosynthetic Gene Clusters via Oligonucleotide Recombineering and CRISPR/Cas9 Targeting | C42: 2 | D42: 2 | E42: 2 | F42: 0 | G42: =D42>0 -> TRUE | H42: =E42>0 -> TRUE | I42: =AND(G42,(D42=E42)) -> TRUE | J42: =(F42>0) -> FALSE | K42: =AND(I42,(E42=F42)) -> FALSE | L42: # Papers
B43: Totals: | C43: =SUM(C2:C32) -> 179 | D43: =SUM(D2:D32) -> 21 | E43: =SUM(E2:E32) -> 19 | F43: =SUM(F2:F32) -> 6 | G43: =COUNTIF(G3:G32,"TRUE") -> 11 | H43: =COUNTIF(H3:H32,"TRUE") -> 10 | I43: =COUNTIF(I3:I32,"TRUE") -> 10 | J43: =COUNTIF(J3:J32,"TRUE") -> 4 | K43: =COUNTIF(K3:K32,"TRUE") -> 4 | L43: =COUNTA(E3:E32) -> 30
E44: % of all papers | G44: =G43/L43 -> 0.36666667 | H44: =H43/L43 -> 0.33333333 | I44: =I43/L43 -> 0.33333333 | J44: =J43/L43 -> 0.13333333 | K44: =K43/L43 -> 0.13333333
E45: % of SBOL-possible papers | H45: =H43/G43 -> 0.90909091 | I45: =I43/G43 -> 0.90909091 | J45: =J43/G43 -> 0.36363636 | K45: =K43/G43 -> 0.36363636
E46: % of all / possible figures | G46: =E43/C43 -> 0.10614525 | H46: =E43/D43 -> 0.9047619

Sheet August
D1: Compliance rubric: | E1: https://docs.google.com/document/d/1vK8DdeN5QbFqKy0h2uLIuuB89hU_Zlj_o41NX1BVtAY/edit?usp=sharing
A2: Article | C2: # Figures | D2: # Appropriate for SBOL Visual | E2: # Compliant with SBOL Visual | F2: Best Practices | G2: SBOL Possible | H2: SBOL Used | I2: SBOL Uniformly Used | J2: Best Practices Used | K2: Best Practices Uniformly Used
A3: Robotic DNA Nanostructures | C3: 6 | D3: 0 | E3: 0 | F3: 0 | G3: =D3>0 -> FALSE | H3: =E3>0 -> FALSE | I3: =AND(G3,(D3=E3)) -> FALSE | J3: =(F3>0) -> FALSE | K3: =AND(I3,(E3=F3)) -> FALSE
A4: Thermal Control of Engineered T-cells | C4: 6 | D4: 5 | E4: 0 | F4: 0 | G4: =D4>0 -> TRUE | H4: =E4>0 -> FALSE | I4: =AND(G4,(D4=E4)) -> FALSE | J4: =(F4>0) -> FALSE | K4: =AND(I4,(E4=F4)) -> FALSE
A5: Lyophilized Cell-Free Systems Display Tolerance to Organic Solvent Exposure | C5: 4 | D5: 0 | E5: 0 | F5: 0 | G5: =D5>0 -> FALSE | H5: =E5>0 -> FALSE | I5: =AND(G5,(D5=E5)) -> FALSE | J5: =(F5>0) -> FALSE | K5: =AND(I5,(E5=F5)) -> FALSE
A6: Activation of Protein Expression in Electroactive Biofilms | C6: 5 | D6: 2 | E6: 2 | F6: 2 | G6: =D6>0 -> TRUE | H6: =E6>0 -> TRUE | I6: =AND(G6,(D6=E6)) -> TRUE | J6: =(F6>0) -> TRUE | K6: =AND(I6,(E6=F6)) -> TRUE
A7: CRISPR/Cas9-Based Genome Editing in the Filamentous Fungus Glarea lozoyensis and Its Application in Manipulating gloF | C7: 5 | D7: 5 | E7: 1 | F7: 0 | G7: =D7>0 -> TRUE | H7: =E7>0 -> TRUE | I7: =AND(G7,(D7=E7)) -> FALSE | J7: =(F7>0) -> FALSE | K7: =AND(I7,(E7=F7)) -> FALSE
A8: Metabolic Engineering of Saccharomyces cerevisiae for Rosmarinic Acid Production | C8: 5 | D8: 1 | E8: 1 | F8: 1 | G8: =D8>0 -> TRUE | H8: =E8>0 -> TRUE | I8: =AND(G8,(D8=E8)) -> TRUE | J8: =(F8>0) -> TRUE | K8: =AND(I8,(E8=F8)) -> TRUE
A9: Identification of the Biosynthetic Gene Cluster for the anti-MRSA Lysocins through Gene Cluster Activation Using Strong Promoters of Housekeeping Genes and Production of New Analogs in Lysobacter sp. 3655 | C9: 5 | D9: 2 | E9: 1 | F9: 1 | G9: =D9>0 -> TRUE | H9: =E9>0 -> TRUE | I9: =AND(G9,(D9=E9)) -> FALSE | J9: =(F9>0) -> TRUE | K9: =AND(I9,(E9=F9)) -> FALSE
A10: Multicopy Chromosomal Integration Using CRISPR-Associated Transposases | C10: 6 | D10: 5 | E10: 5 | F10: 0 | G10: =D10>0 -> TRUE | H10: =E10>0 -> TRUE | I10: =AND(G10,(D10=E10)) -> TRUE | J10: =(F10>0) -> FALSE | K10: =AND(I10,(E10=F10)) -> FALSE
A11: Reassembly of the Biosynthetic Gene Cluster Enables High Epothilone Yield in Engineered Schlegelella brevitalea | C11: 8 | D11: 1 | E11: 1 | F11: 0 | G11: =D11>0 -> TRUE | H11: =E11>0 -> TRUE | I11: =AND(G11,(D11=E11)) -> TRUE | J11: =(F11>0) -> FALSE | K11: =AND(I11,(E11=F11)) -> FALSE
A12: Inducible Expression Systems Based on Xenogeneic Silencing and Counter-Silencing and Design of a Metabolic Toggle Switch | C12: 6 | D12: 5 | E12: 5 | F12: 0 | G12: =D12>0 -> TRUE | H12: =E12>0 -> TRUE | I12: =AND(G12,(D12=E12)) -> TRUE | J12: =(F12>0) -> FALSE | K12: =AND(I12,(E12=F12)) -> FALSE
A13: Engineering REST-Specific Synthetic PUF Proteins to Control Neuronal Gene Expression: A Combined Experimental and Computational Study | C13: 7 | D13: 0 | E13: 0 | F13: 0 | G13: =D13>0 -> FALSE | H13: =E13>0 -> FALSE | I13: =AND(G13,(D13=E13)) -> FALSE | J13: =(F13>0) -> FALSE | K13: =AND(I13,(E13=F13)) -> FALSE
A14: Engineering and Rewiring of a Calcium-Dependent Signaling Pathway | C14: 5 | D14: 5 | E14: 0 | F14: 0 | G14: =D14>0 -> TRUE | H14: =E14>0 -> FALSE | I14: =AND(G14,(D14=E14)) -> FALSE | J14: =(F14>0) -> FALSE | K14: =AND(I14,(E14=F14)) -> FALSE
... A29: Expanding Toolbox for Genes Expression of Yarrowia lipolytica to Include Novel Inducible, Repressible, and Hybrid Promoters | C29: 2 | D29: 0 | E29: 0 | F29: 0 | G29: =D29>0 -> FALSE | H29: =E29>0 -> FALSE | I29: =AND(G29,(D29=E29)) -> FALSE | J29: =(F29>0) -> FALSE | K29: =AND(I29,(E29=F29)) -> FALSE
B30: Totals: | C30: =SUM(C2:C29) -> 139 | D30: =SUM(D2:D29) -> 47 | E30: =SUM(E2:E29) -> 28 | F30: =SUM(F2:F29) -> 11 | G30: =COUNTIF(G3:G29,"TRUE") -> 18 | H30: =COUNTIF(H3:H29,"TRUE") -> 13 | I30: =COUNTIF(I3:I29,"TRUE") -> 11 | J30: =COUNTIF(J3:J29,"TRUE") -> 7 | K30: =COUNTIF(K3:K29,"TRUE") -> 5 | L30: =COUNTA(E3:E29) -> 27
E31: % of all papers | G31: =G30/L30 -> 0.66666667 | H31: =H30/L30 -> 0.48148148 | I31: =I30/L30 -> 0.40740741 | J31: =J30/L30 -> 0.25925926 | K31: =K30/L30 -> 0.18518519
E32: % of SBOL-possible papers | H32: =H30/G30 -> 0.72222222 | I32: =I30/G30 -> 0.61111111 | J32: =J30/G30 -> 0.38888889 | K32: =K30/G30 -> 0.27777778
E33: % of all / possible figures | G33: =E30/C30 -> 0.20143885 | H33: =E30/D30 -> 0.59574468

Sheet September
D1: Compliance rubric: | E1: https://docs.google.com/document/d/1vK8DdeN5QbFqKy0h2uLIuuB89hU_Zlj_o41NX1BVtAY/edit?usp=sharing
A2: Article | C2: # Figures | D2: # Appropriate for SBOL Visual | E2: # Compliant with SBOL Visual | F2: Best Practices | G2: SBOL Possible | H2: SBOL Used | I2: SBOL Uniformly Used | J2: Best Practices Used | K2: Best Practices Uniformly Used
A3: Engineering Critical Enzymes and Pathways for Improved Triterpenoid Biosynthesis in Yeast | C3: 5 | D3: 0 | E3: 0 | F3: 0 | G3: =D3>0 -> FALSE | H3: =E3>0 -> FALSE | I3: =AND(G3,(D3=E3)) -> FALSE | J3: =(F3>0) -> FALSE | K3: =AND(I3,(E3=F3)) -> FALSE
A4: Applications of CRISPR in a Microbial Cell Factory: From Genome Reconstruction to Metabolic Network Reprogramming | C4: 2 | D4: 3 | E4: 3 | F4: 0 | G4: =D4>0 -> TRUE | H4: =E4>0 -> TRUE | I4: =AND(G4,(D4=E4)) -> TRUE | J4: =(F4>0) -> FALSE | K4: =AND(I4,(E4=F4)) -> FALSE
A5: Engineering Isoprenoid Quinone Production in Yeast | C5: 3 | D5: 0 | E5: 0 | F5: 0 | G5: =D5>0 -> FALSE | H5: =E5>0 -> FALSE | I5: =AND(G5,(D5=E5)) -> FALSE | J5: =(F5>0) -> FALSE | K5: =AND(I5,(E5=F5)) -> FALSE
A6: Display of Self-Peptide on Adeno-Associated Virus Capsid Decreases Phagocytic Uptake in Vitro | C6: 4 | D6: 0 | E6: 0 | F6: 0 | G6: =D6>0 -> FALSE | H6: =E6>0 -> FALSE | I6: =AND(G6,(D6=E6)) -> FALSE | J6: =(F6>0) -> FALSE | K6: =AND(I6,(E6=F6)) -> FALSE
A7: A Single Cas9-VPR Nuclease for Simultaneous Gene Activation, Repression, and Editing in Saccharomyces cerevisiae | C7: 3 | D7: 0 | E7: 0 | F7: 0 | G7: =D7>0 -> FALSE | H7: =E7>0 -> FALSE | I7: =AND(G7,(D7=E7)) -> FALSE | J7: =(F7>0) -> FALSE | K7: =AND(I7,(E7=F7)) -> FALSE
A8: FlopR: An Open Source Software Package for Calibration and Normalization of Plate Reader and Flow Cytometry Data | C8: 4 | D8: 1 | E8: 1 | F8: 1 | G8: =D8>0 -> TRUE | H8: =E8>0 -> TRUE | I8: =AND(G8,(D8=E8)) -> TRUE | J8: =(F8>0) -> TRUE | K8: =AND(I8,(E8=F8)) -> TRUE
A9: Rapid Fabrication of Protein Microarrays via Autogeneration and on-Chip Purification of Biotinylated Probes | C9: 6 | D9: 1 | E9: 1 | F9: 0 | G9: =D9>0 -> TRUE | H9: =E9>0 -> TRUE | I9: =AND(G9,(D9=E9)) -> TRUE | J9: =(F9>0) -> FALSE | K9: =AND(I9,(E9=F9)) -> FALSE
A10: CL6mN: Rationally Designed Optogenetic Photoswitches with Tunable Dissociation Dynamics | C10: 6 | D10: 0 | E10: 0 | F10: 0 | G10: =D10>0 -> FALSE | H10: =E10>0 -> FALSE | I10: =AND(G10,(D10=E10)) -> FALSE | J10: =(F10>0) -> FALSE | K10: =AND(I10,(E10=F10)) -> FALSE
A11: Constructing Microbial Hosts for the Production of Benzoheterocyclic Derivatives | C11: 5 | D11: 0 | E11: 0 | F11: 0 | G11: =D11>0 -> FALSE | H11: =E11>0 -> FALSE | I11: =AND(G11,(D11=E11)) -> FALSE | J11: =(F11>0) -> FALSE | K11: =AND(I11,(E11=F11)) -> FALSE
A12: Optogenetic Control of Heterologous Metabolism in E. coli | C12: 6 | D12: 1 | E12: 1 | F12: 0 | G12: =D12>0 -> TRUE | H12: =E12>0 -> TRUE | I12: =AND(G12,(D12=E12)) -> TRUE | J12: =(F12>0) -> FALSE | K12: =AND(I12,(E12=F12)) -> FALSE
A13: Tuning Extracellular Electron Transfer by Shewanella oneidensis Using Transcriptional Logic Gates | C13: 6 | D13: 4 | E13: 4 | F13: 4 | G13: =D13>0 -> TRUE | H13: =E13>0 -> TRUE | I13: =AND(G13,(D13=E13)) -> TRUE | J13: =(F13>0) -> TRUE | K13: =AND(I13,(E13=F13)) -> TRUE
A14: Conditional Recruitment to a DNA-Bound CRISPR–Cas Complex Using a Colocalization-Dependent Protein Switch | C14: 5 | D14: 4 | E14: 4 | F14: 0 | G14: =D14>0 -> TRUE | H14: =E14>0 -> TRUE | I14: =AND(G14,(D14=E14)) -> TRUE | J14: =(F14>0) -> FALSE | K14: =AND(I14,(E14=F14)) -> FALSE
... A40: CRAGE-Duet Facilitates Modular Assembly of Biological Systems for Studying Plant–Microbe Interactions | C40: 2 | D40: 1 | E40: 1 | F40: 0 | G40: =D40>0 -> TRUE | H40: =E40>0 -> TRUE | I40: =AND(G40,(D40=E40)) -> TRUE | J40: =(F40>0) -> FALSE | K40: =AND(I40,(E40=F40)) -> FALSE
B41: Totals: | C41: =SUM(C2:C32) -> 181 | D41: =SUM(D2:D32) -> 51 | E41: =SUM(E2:E32) -> 37 | F41: =SUM(F2:F32) -> 16 | G41: =COUNTIF(G3:G32,"TRUE") -> 20 | H41: =COUNTIF(H3:H32,"TRUE") -> 14 | I41: =COUNTIF(I3:I32,"TRUE") -> 14 | J41: =COUNTIF(J3:J32,"TRUE") -> 6 | K41: =COUNTIF(K3:K32,"TRUE") -> 6 | L41: =COUNTA(E3:E32) -> 30
E42: % of all papers | G42: =G41/L41 -> 0.66666667 | H42: =H41/L41 -> 0.46666667 | I42: =I41/L41 -> 0.46666667 | J42: =J41/L41 -> 0.2 | K42: =K41/L41 -> 0.2
E43: % of SBOL-possible papers | H43: =H41/G41 -> 0.7 | I43: =I41/G41 -> 0.7 | J43: =J41/G41 -> 0.3 | K43: =K41/G41 -> 0.3
E44: % of all / possible figures | G44: =E41/C41 -> 0.20441989 | H44: =E41/D41 -> 0.7254902

Sheet October
D1: Compliance rubric: | E1: https://docs.google.com/document/d/1vK8DdeN5QbFqKy0h2uLIuuB89hU_Zlj_o41NX1BVtAY/edit?usp=sharing
A2: Article | C2: # Figures | D2: # Appropriate for SBOL Visual | E2: # Compliant with SBOL Visual | F2: Best Practices | G2: SBOL Possible | H2: SBOL Used | I2: SBOL Uniformly Used | J2: Best Practices Used | K2: Best Practices Uniformly Used
A3: In Vivo Feedback Control of an Antithetic Molecular-Titration Motif in Escherichia coli Using Microfluidics | C3: 4 | D3: 1 | E3: 1 | F3: 1 | G3: =D3>0 -> TRUE | H3: =E3>0 -> TRUE | I3: =AND(G3,(D3=E3)) -> TRUE | J3: =(F3>0) -> TRUE | K3: =AND(I3,(E3=F3)) -> TRUE
A4: Engineering a Synthesis-Friendly Constitutive Promoter for Mammalian Cell Expression | C4: 4 | D4: 3 | E4: 0 | F4: 0 | G4: =D4>0 -> TRUE | H4: =E4>0 -> FALSE | I4: =AND(G4,(D4=E4)) -> FALSE | J4: =(F4>0) -> FALSE | K4: =AND(I4,(E4=F4)) -> FALSE
A5: Construction of Fully Segregated Genomic Libraries in Polyploid Organisms Such as Synechocystis sp. PCC 6803 | C5: 3 | D5: 2 | E5: 2 | F5: 0 | G5: =D5>0 -> TRUE | H5: =E5>0 -> TRUE | I5: =AND(G5,(D5=E5)) -> TRUE | J5: =(F5>0) -> FALSE | K5: =AND(I5,(E5=F5)) -> FALSE
A6: Conditional Protein Rescue by Binding-Induced Protective Shielding | C6: 7 | D6: 1 | E6: 0 | F6: 0 | G6: =D6>0 -> TRUE | H6: =E6>0 -> FALSE | I6: =AND(G6,(D6=E6)) -> FALSE | J6: =(F6>0) -> FALSE | K6: =AND(I6,(E6=F6)) -> FALSE
A7: In Vitro Selection of RNA Aptamers Binding to Nanosized DNA for Constructing Artificial Riboswitches | C7: 5 | D7: 0 | E7: 0 | F7: 0 | G7: =D7>0 -> FALSE | H7: =E7>0 -> FALSE | I7: =AND(G7,(D7=E7)) -> FALSE | J7: =(F7>0) -> FALSE | K7: =AND(I7,(E7=F7)) -> FALSE
A8: Securing the Exchange of Synthetic Genetic Constructs Using Digital Signatures | C8: 4 | D8: 2 | E8: 2 | F8: 0 | G8: =D8>0 -> TRUE | H8: =E8>0 -> TRUE | I8: =AND(G8,(D8=E8)) -> TRUE | J8: =(F8>0) -> FALSE | K8: =AND(I8,(E8=F8)) -> FALSE
A9: A Unified Dynamic Programming Framework for the Analysis of Interacting Nucleic Acid Strands: Enhanced Models, Scalability, and Speed | C9: 15 | D9: 0 | E9: 0 | F9: 0 | G9: =D9>0 -> FALSE | H9: =E9>0 -> FALSE | I9: =AND(G9,(D9=E9)) -> FALSE | J9: =(F9>0) -> FALSE | K9: =AND(I9,(E9=F9)) -> FALSE
A10: Meganuclease-Based Artificial Transcription Factors | C10: 8 | D10: 3 | E10: 0 | F10: 0 | G10: =D10>0 -> TRUE | H10: =E10>0 -> FALSE | I10: =AND(G10,(D10=E10)) -> FALSE | J10: =(F10>0) -> FALSE | K10: =AND(I10,(E10=F10)) -> FALSE
A11: Homologous Quorum Sensing Regulatory Circuit: A Dual-Input Genetic Controller for Modulating Quorum Sensing-Mediated Protein Expression in E. coli | C11: 5 | D11: 2 | E11: 2 | F11: 2 | G11: =D11>0 -> TRUE | H11: =E11>0 -> TRUE | I11: =AND(G11,(D11=E11)) -> TRUE | J11: =(F11>0) -> TRUE | K11: =AND(I11,(E11=F11)) -> TRUE
A12: An Amino Acid-Swapped Genetic Code | C12: 5 | D12: 0 | E12: 0 | F12: 0 | G12: =D12>0 -> FALSE | H12: =E12>0 -> FALSE | I12: =AND(G12,(D12=E12)) -> FALSE | J12: =(F12>0) -> FALSE | K12: =AND(I12,(E12=F12)) -> FALSE
A13: Design, Evolution, and Characterization of a Xylose Biosensor in Escherichia coli Using the XylR/xylO System with an Expanded Operating Range | C13: 8 | D13: 1 | E13: 1 | F13: 0 | G13: =D13>0 -> TRUE | H13: =E13>0 -> TRUE | I13: =AND(G13,(D13=E13)) -> TRUE | J13: =(F13>0) -> FALSE | K13: =AND(I13,(E13=F13)) -> FALSE
A14: Thermophilic Pyrrolysyl-tRNA Synthetase Mutants for Enhanced Mammalian Genetic Code Expansion | C14: 6 | D14: 0 | E14: 0 | F14: 0 | G14: =D14>0 -> FALSE | H14: =E14>0 -> FALSE | I14: =AND(G14,(D14=E14)) -> FALSE | J14: =(F14>0) -> FALSE | K14: =AND(I14,(E14=F14)) -> FALSE
... A25: Protecting Linear DNA Templates in Cell-Free Expression Systems from Diverse Bacteria | C25: 2 | D25: 1 | E25: 1 | F25: 1 | G25: =D25>0 -> TRUE | H25: =E25>0 -> TRUE | I25: =AND(G25,(D25=E25)) -> TRUE | J25: =(F25>0) -> TRUE | K25: =AND(I25,(E25=F25)) -> TRUE
B26: Totals: | C26: =SUM(C2:C25) -> 125 | D26: =SUM(D2:D25) -> 28 | E26: =SUM(E2:E25) -> 14 | F26: =SUM(F2:F25) -> 6 | G26: =COUNTIF(G3:G25,"TRUE") -> 14 | H26: =COUNTIF(H3:H25,"TRUE") -> 10 | I26: =COUNTIF(I3:I25,"TRUE") -> 9 | J26: =COUNTIF(J3:J25,"TRUE") -> 4 | K26: =COUNTIF(K3:K25,"TRUE") -> 4 | L26: =COUNTA(E3:E25) -> 23
E27: % of all papers | G27: =G26/L26 -> 0.60869565 | H27: =H26/L26 -> 0.43478261 | I27: =I26/L26 -> 0.39130435 | J27: =J26/L26 -> 0.17391304 | K27: =K26/L26 -> 0.17391304
E28: % of SBOL-possible papers | H28: =H26/G26 -> 0.71428571 | I28: =I26/G26 -> 0.64285714 | J28: =J26/G26 -> 0.28571429 | K28: =K26/G26 -> 0.28571429
E29: % of all / possible figures | G29: =E26/C26 -> 0.112 | H29: =E26/D26 -> 0.5

Sheet November
D1: Compliance rubric: | E1: https://docs.google.com/document/d/1vK8DdeN5QbFqKy0h2uLIuuB89hU_Zlj_o41NX1BVtAY/edit?usp=sharing
A2: Article | C2: # Figures | D2: # Appropriate for SBOL Visual | E2: # Compliant with SBOL Visual | F2: Best Practices | G2: SBOL Possible | H2: SBOL Used | I2: SBOL Uniformly Used | J2: Best Practices Used | K2: Best Practices Uniformly Used
A3: Isothermal SARS-CoV-2 Diagnostics: Tools for Enabling Distributed Pandemic Testing as a Means of Supporting Safe Reopenings | C3: 10 | D3: 0 | E3: 0 | F3: 0 | G3: =D3>0 -> FALSE | H3: =E3>0 -> FALSE | I3: =AND(G3,(D3=E3)) -> FALSE | J3: =(F3>0) -> FALSE | K3: =AND(I3,(E3=F3)) -> FALSE
A4: Compartmentalizing Cell-Free Systems: Toward Creating Life-Like Artificial Cells and Beyond | C4: 5 | D4: 0 | E4: 0 | F4: 0 | G4: =D4>0 -> FALSE | H4: =E4>0 -> FALSE | I4: =AND(G4,(D4=E4)) -> FALSE | J4: =(F4>0) -> FALSE | K4: =AND(I4,(E4=F4)) -> FALSE
A5: Synthesis of Ligustrazine from Acetaldehyde by a Combined Biological–Chemical Approach | C5: 3 | D5: 0 | E5: 0 | F5: 0 | G5: =D5>0 -> FALSE | H5: =E5>0 -> FALSE | I5: =AND(G5,(D5=E5)) -> FALSE | J5: =(F5>0) -> FALSE | K5: =AND(I5,(E5=F5)) -> FALSE
A6: Artificial ER-Derived Vesicles as Synthetic Organelles for in Vivo Compartmentalization of Biochemical Pathways | C6: 3 | D6: 0 | E6: 0 | F6: 0 | G6: =D6>0 -> FALSE | H6: =E6>0 -> FALSE | I6: =AND(G6,(D6=E6)) -> FALSE | J6: =(F6>0) -> FALSE | K6: =AND(I6,(E6=F6)) -> FALSE
A7: Multidimensional Characterization of Parts Enhances Modeling Accuracy in Genetic Circuits | C7: 3 | D7: 3 | E7: 3 | F7: 0 | G7: =D7>0 -> TRUE | H7: =E7>0 -> TRUE | I7: =AND(G7,(D7=E7)) -> TRUE | J7: =(F7>0) -> FALSE | K7: =AND(I7,(E7=F7)) -> FALSE
A8: Discovery of Novel Gain-of-Function Mutations Guided by Structure-Based Deep Learning | C8: 3 | D8: 0 | E8: 0 | F8: 0 | G8: =D8>0 -> FALSE | H8: =E8>0 -> FALSE | I8: =AND(G8,(D8=E8)) -> FALSE | J8: =(F8>0) -> FALSE | K8: =AND(I8,(E8=F8)) -> FALSE
A9: Reading and Writing Digital Information in TNA | C9: 5 | D9: 0 | E9: 0 | F9: 0 | G9: =D9>0 -> FALSE | H9: =E9>0 -> FALSE | I9: =AND(G9,(D9=E9)) -> FALSE | J9: =(F9>0) -> FALSE | K9: =AND(I9,(E9=F9)) -> FALSE
A10: Integrative Biosynthetic Gene Cluster Mining to Optimize a Metabolic Pathway to Efficiently Produce l-Homophenylalanine in Escherichia coli | C10: 7 | D10: 3 | E10: 3 | F10: 0 | G10: =D10>0 -> TRUE | H10: =E10>0 -> TRUE | I10: =AND(G10,(D10=E10)) -> TRUE | J10: =(F10>0) -> FALSE | K10: =AND(I10,(E10=F10)) -> FALSE
A11: Genetically Encoded Fluorescent Biosensor for Rapid Detection of Protein Expression | C11: 3 | D11: 0 | E11: 0 | F11: 0 | G11: =D11>0 -> FALSE | H11: =E11>0 -> FALSE | I11: =AND(G11,(D11=E11)) -> FALSE | J11: =(F11>0) -> FALSE | K11: =AND(I11,(E11=F11)) -> FALSE
A12: Design of Multipartite Transcription Factors for Multiplexed Logic Genome Integration Control in Mammalian Cells | C12: 4 | D12: 3 | E12: 0 | F12: 0 | G12: =D12>0 -> TRUE | H12: =E12>0 -> FALSE | I12: =AND(G12,(D12=E12)) -> FALSE | J12: =(F12>0) -> FALSE | K12: =AND(I12,(E12=F12)) -> FALSE
A13: Microcompartmentalized Cell-Free Protein Synthesis in Hydrogel μ-Channels | C13: 4 | D13: 0 | E13: 0 | F13: 0 | G13: =D13>0 -> FALSE | H13: =E13>0 -> FALSE | I13: =AND(G13,(D13=E13)) -> FALSE | J13: =(F13>0) -> FALSE | K13: =AND(I13,(E13=F13)) -> FALSE
A14: Biosynthesis of the Calorie-Free Sweetener Precursor ent-Kaurenoic Acid from CO2 Using Engineered Cyanobacteria | C14: 3 | D14: 1 | E14: 1 | F14: 1 | G14: =D14>0 -> TRUE | H14: =E14>0 -> TRUE | I14: =AND(G14,(D14=E14)) -> TRUE | J14: =(F14>0) -> TRUE | K14: =AND(I14,(E14=F14)) -> TRUE
... A31: A Lambda Red and FLP/FRT-Mediated Site-Specific Recombination System in Komagataeibacter xylinus and Its Application to Enhance the Productivity of Bacterial Cellulose | C31: 4 | D31: 1 | E31: 1 | F31: 0 | G31: =D31>0 -> TRUE | H31: =E31>0 -> TRUE | I31: =AND(G31,(D31=E31)) -> TRUE | J31: =(F31>0) -> FALSE | K31: =AND(I31,(E31=F31)) -> FALSE
B32: Totals: | C32: =SUM(C2:C31) -> 145 | D32: =SUM(D2:D31) -> 32 | E32: =SUM(E2:E31) -> 25 | F32: =SUM(F2:F31) -> 9 | G32: =COUNTIF(G3:G31,"TRUE") -> 15 | H32: =COUNTIF(H3:H31,"TRUE") -> 13 | I32: =COUNTIF(I3:I31,"TRUE") -> 11 | J32: =COUNTIF(J3:J31,"TRUE") -> 6 | K32: =COUNTIF(K3:K31,"TRUE") -> 5 | L32: =COUNTA(E3:E31) -> 29
E33: % of all papers | G33: =G32/L32 -> 0.51724138 | H33: =H32/L32 -> 0.44827586 | I33: =I32/L32 -> 0.37931034 | J33: =J32/L32 -> 0.20689655 | K33: =K32/L32 -> 0.17241379
E34: % of SBOL-possible papers | H34: =H32/G32 -> 0.86666667 | I34: =I32/G32 -> 0.73333333 | J34: =J32/G32 -> 0.4 | K34: =K32/G32 -> 0.33333333
E35: % of all / possible figures | G35: =E32/C32 -> 0.17241379 | H35: =E32/D32 -> 0.78125

Sheet December
D1: Compliance rubric: | E1: https://docs.google.com/document/d/1vK8DdeN5QbFqKy0h2uLIuuB89hU_Zlj_o41NX1BVtAY/edit?usp=sharing
A2: Article | C2: # Figures | D2: # Appropriate for SBOL Visual | E2: # Compliant with SBOL Visual | F2: Best Practices | G2: SBOL Possible | H2: SBOL Used | I2: SBOL Uniformly Used | J2: Best Practices Used | K2: Best Practices Uniformly Used
A3: Engineering Microbiomes—Looking Ahead | C3: 2 | D3: 0 | E3: 0 | F3: 0 | G3: =D3>0 -> FALSE | H3: =E3>0 -> FALSE | I3: =AND(G3,(D3=E3)) -> FALSE | J3: =(F3>0) -> FALSE | K3: =AND(I3,(E3=F3)) -> FALSE
A4: Living Therapeutics: The Next Frontier of Precision Medicine | C4: 4 | D4: 2 | E4: 2 | F4: 2 | G4: =D4>0 -> TRUE | H4: =E4>0 -> TRUE | I4: =AND(G4,(D4=E4)) -> TRUE | J4: =(F4>0) -> TRUE | K4: =AND(I4,(E4=F4)) -> TRUE
A5: Fine-Tuning of Transcription in Pichia pastoris Using dCas9 and RNA Scaffolds | C5: 4 | D5: 2 | E5: 0 | F5: 0 | G5: =D5>0 -> TRUE | H5: =E5>0 -> FALSE | I5: =AND(G5,(D5=E5)) -> FALSE | J5: =(F5>0) -> FALSE | K5: =AND(I5,(E5=F5)) -> FALSE
A6: A Logic NAND Gate for Controlling Gene Expression in a Circadian Rhythm in Cyanobacteria | C6: 3 | D6: 3 | E6: 3 | F6: 3 | G6: =D6>0 -> TRUE | H6: =E6>0 -> TRUE | I6: =AND(G6,(D6=E6)) -> TRUE | J6: =(F6>0) -> TRUE | K6: =AND(I6,(E6=F6)) -> TRUE
A7: PATHcre8: A Tool That Facilitates the Searching for Heterologous Biosynthetic Routes | C7: 4 | D7: 0 | E7: 0 | F7: 0 | G7: =D7>0 -> FALSE | H7: =E7>0 -> FALSE | I7: =AND(G7,(D7=E7)) -> FALSE | J7: =(F7>0) -> FALSE | K7: =AND(I7,(E7=F7)) -> FALSE
A8: Automating Cloning by Natural Transformation | C8: 5 | D8: 4 | E8: 4 | F8: 4 | G8: =D8>0 -> TRUE | H8: =E8>0 -> TRUE | I8: =AND(G8,(D8=E8)) -> TRUE | J8: =(F8>0) -> TRUE | K8: =AND(I8,(E8=F8)) -> TRUE
